Workbook
Name _R01: LGU_Masterlist!$E$3:$E$9
Name _R02: LGU_Masterlist!$F$3:$F$9
Name _R03: LGU_Masterlist!$G$3:$G$9
Name _R04_A: LGU_Masterlist!$H$4:$H$9
Name _R04_B: LGU_Masterlist!$I$3:$I$9
Name _R05: LGU_Masterlist!$J$3:$J$9
Name _R06: LGU_Masterlist!$K$3:$K$9
Name _R07: LGU_Masterlist!$M$3:$M$9
Name _R08: LGU_Masterlist!$N$3:$N$9
Name _R09: LGU_Masterlist!$O$3:$O$9
Name _R10: LGU_Masterlist!$P$3:$P$9
Name _R11: LGU_Masterlist!$Q$3:$Q$9
Name _R12: LGU_Masterlist!$R$3:$R$9
Name _R13: LGU_Masterlist!$S$3:$S$9
Name Abra: LGU_Masterlist!$C$12:$C$38
Name Agusan_del_Norte: LGU_Masterlist!$BW$12:$BW$23
Name Agusan_del_Sur: LGU_Masterlist!$BX$12:$BX$25
Name Aklan: LGU_Masterlist!$AO$12:$AO$28
Name Albay: LGU_Masterlist!$AI$12:$AI$29
Name Antique: LGU_Masterlist!$AP$12:$AP$30
Name Apayao: LGU_Masterlist!$D$12:$D$18
Name Aurora: LGU_Masterlist!$X$12:$X$19
Name BARMM: LGU_Masterlist!$B$3:$B$7
Name Basilan: LGU_Masterlist!$BH$12
Name Bataan: LGU_Masterlist!$R$12:$R$23
Name Batanes: LGU_Masterlist!$M$12:$M$17
Name Batangas: LGU_Masterlist!$Y$12:$Y$45
Name Benguet: LGU_Masterlist!$E$12:$E$25
Name Biliran: LGU_Masterlist!$BD$12:$BD$19
Name Bohol: LGU_Masterlist!$AW$12:$AW$59
Name Bukidnon: LGU_Masterlist!$BI$12:$BI$33
Name Bulacan: LGU_Masterlist!$S$12:$S$35
Name Cagayan: LGU_Masterlist!$N$12:$N$40
Name Camarines_Norte: LGU_Masterlist!$AJ$12:$AJ$23
Name Camarines_Sur: LGU_Masterlist!$AK$12:$AK$48
Name Camiguin: LGU_Masterlist!$BJ$12:$BJ$16
Name Capiz: LGU_Masterlist!$AQ$12:$AQ$28
Name CAR: LGU_Masterlist!$E$3:$E$8
Name Catanduanes: LGU_Masterlist!$AL$12:$AL$22
Name Cavite: LGU_Masterlist!$Z$12:$Z$34
Name Cebu: LGU_Masterlist!$AX$12:$AX$64
Name cit_mun: LGU_Table!$C$2:$C$1635
Name cm_class: LGU_Table!$G$2:$G$1635
Name Cordilla_Administrative_Region: LGU_Masterlist!$D$3:$D$8
Name Cotabato: LGU_Masterlist!$BS$12:$BS$29
Name Davao_de_Oro: LGU_Masterlist!$BQ$12:$BQ$22
Name Davao_del_Norte: LGU_Masterlist!$BN$12:$BN$22
Name Davao_del_Sur: LGU_Masterlist!$BO$12:$BO$22
Name Davao_Occidental: LGU_Masterlist!$BR$12:$BR$16
Name Davao_Oriental: LGU_Masterlist!$BP$12:$BP$22
Name Dinagat_Islands: LGU_Masterlist!$CA$12:$CA$18
Name Eastern_Samar: LGU_Masterlist!$AY$12:$AY$34
Name Guimaras: LGU_Masterlist!$AS$12:$AS$16
Name h_sett: LGU_Table!$F$2:$F$1635
Name Ifugao: LGU_Masterlist!$F$12:$F$22
Name Ilocos_Norte: LGU_Masterlist!$I$12:$I$34
Name Ilocos_Sur: LGU_Masterlist!$J$12:$J$45
Name Iloilo: LGU_Masterlist!$AR$12:$AR$55
Name inc_class: LGU_Table!$H$2:$H$1635
Name Isabela: LGU_Masterlist!$O$12:$O$48

Sheet LGU2

Sheet Regions
A1: regions
A2: BARMM
A3: Cordillera Administrative Region
A4: National Capital Region
A5: Region 01 (Ilocos Region)
A6: Region 02 (Cagayan Valley)
A7: Region 03 (Central Luzon)
A8: Region 04-A (CALABARZON)
A9: Region 04-B (MIMAROPA)
A10: Region 05 (Bicol Region)
A11: Region 06 (Western Visayas)
A12: Region 07 (Central Visayas Region)
... A18: Region 13 (Caraga Region)

Sheet Home
A1: MONTHLY ACCOMPLISHMENT COLLECTION AND REPORTING MANUAL
A2: ENVIRONMENTAL, LAND USE AND URBAN PLANNING AND DEVELOPMENT DIVISION (ELUPDD)
A4: OVERVIEW AND RATIONALE
A6: The Monthly Accomplishment Collection and Reporting Manual was primarily developed to serve as a reference guide for the Monitoring and Evaluation Focal Persons of the DHSUD Regional Offices (ROs) - Environmental, Land Use, and Urban Planning and Development Division (ELUPDD) in the data collection and reporting of their accomplishments pursuant to ELUPDD’s functions and DHSUD’s mandates and programs. This tool consolidates the accomplishment indicators and targets to be collected and reported in ELUPDD's accomplishment report as agreed with the Central Office. Moreover, this tool was developed to monitor and report process, activities, and functions of ELUPDD pursuant to DHSUD’s Operations Manual and Quality Management System (QMS).
A8: ACCOMPLISHMENT REPORTING PROCESS
A10: The Accomplishment reports submitted by the ELUPDD are consolidated, processed, and reported by ELUPDB. The processed reports are submitted by ELUPDB internally to the DHSUD Planning Service (PS) and/or DHSUD Executive Offices (Office of Assistant Secretary, Office of Undersecretary, Office of Secretary) and externally, to National Government Agencies, Legislature (Congress and Senate), Executive Offices including the Office of the President, International Funding Agencies, and other stakeholders. The accomplishment reports serve as a measure of success in attaining the tasks and functions mandated to the DHSUD specifically to ELUPDD. Furthermore, the accomplishment report shall be a basis for additional support (mainly financial) from the National Government and/or International Funding Agencies to DHSUD and ELUPDD.
B11: `
A12: UPDATING, AND SCOPE AND LIMITATIONS
A14: Mid-year and end-of-year assessment and updating activities will be held among ELUPDB’s Monitoring and Evaluation Division and ELUPDD’s Monitoring and Evaluation Focal Persons. These activities shall ensure that the tool and the manual is updated and adaptive to the most important programs to solve societal issues. If in need of updating, the new version of the tool and manual shall be released a month after the Mid-year and/or the End-of-Year assessment and updating activity. The data and indicators included in this manual shall only cover ELUPDD and ELUPDB accomplishments of functions as mandated by law or programs required by the direction of the DHSUD Secretary.
B17: Regional ELUPDD Functions as Mandated by Law
A18: GENERAL FUNCTIONS OF REGIONAL OFFICES AS PER IRR OF RA 11201
A19: 24.1 | B19: Implement laws, and the Department's policies, plans, programs, projects, rules and regulations;
A20: 24.2 | B20: Coordinate and maintain linkage with NGAs, LGUs, private entities, NGOs, CSOs, academe, and other stakeholders;
A21: 24.3 | B21: Act on applications for the issuance of various permits, licenses, clearances and certifications;
A22: 24.4 | B22: Conduct conciliation proceedings on issues and disputes relating to the implementation of the Department's mandates, including the regulation of real estate development and HOAs; and
A23: 24.5 | B23: Perform such other functions that are implied, necessary or incidental in carryi out the above or as may be assigned by the Secretary
A25: CORE FUNCTIONS AS PER IRR OF RA 11201
A26: Environmental, Land Use and Urban Planning and Development Functions
A27: 25.1.1 | B27: Provide technical assistance to provinces, cities and municipalities in the preparation and updating of CLUPs, ZOs, and PCLUPs/PPFPs;
A28: 25.1.2 | B28: Conduct technology transfer and capability building programs for LGUs in the implementation of CLUP and ZO enforcement and development control;
A29: 25.1.3 | B29: Conduct training and mentoring in addressing urban development, management and governance concerns such as housing, establishment of government centers, new towns, settlements, and planned unit development, urban renewal, open spaces, traffic concerns, sewerage, waste management, and energy efficiency, among others;
A30: 25.1.4 | B30: Undertake review of PPFPs, CLUPs and ZOs of provinces, cities and municipalities as a member of the Provincial Land Use Committee or Regional Land Use Committee;
A31: 25.1.5 | B31: Extend technical assistance to and conduct technology transfer and capability building of cities and municipalities in the formulation, legitimization and implementation of LSPs, which shall include plans and strategies for the utilization of the socialized housing tax as provided under Section 43 of RA 7279 and other sources of funds for housing and urban development;
A32: 25.1.6 | B32: Monitor land use changes, particularly the reclassification of agricultural lands into other uses and implementation of ZOs of cities and municipalities;
A33: 25.1.7 | B33: Update an inventory of idle lands, existing CLUPs, ZOs, PCLUPs/PPFPs, and LSPs, inventory of housing stock and listing of government-housing program beneficiaries;
A34: 25.1.8 | B34: Maintain a geographic information system for monitoring of land use and zoning particularly on but not limited to:
B35: (a) Compliance of LGUs to guidelines set by the Department in preparing and updating their respective CLUPs and ZOs; and
B36: (b) Implementation of CLUPs and ZOs through monitoring of land use changes and reclassification; and
A37: 25.1.9 | B37: Perform such other functions that are implied, necessary or incide tal in carrying out the above or as may be assigned by the Regional Directors.

Sheet LGU_Masterlist
A1: PROVINCES
B2: BARMM | C2: PLGU | D2: NCR | E2: CAR | F2: RO_1 | G2: RO_2 | H2: RO_3 | I2: RO_4A | J2: RO_4B | K2: RO_5 | L2: RO_6 | M2: NIR | N2: RO_7 | O2: RO_8 | P2: RO_9 | Q2: R_10 | R2: R_11 | S2: R_12 | T2: R_13
B3: Basilan | C3: Province_PLGU | D3: Metro_Manila | E3: Abra | F3: Ilocos_Norte | G3: Batanes | H3: Aurora | I3: Batangas | J3: Marinduque | K3: Albay | L3: Aklan | M3: Negros_Occidental | N3: Bohol | O3: Biliran | P3: Zamboanga_del_Norte | Q3: Bukidnon | R3: Davao_del_Norte | S3: Cotabato | T3: Agusan_del_Norte
B4: Lanao_del_Sur | E4: Apayao | F4: Ilocos_Sur | G4: Cagayan | H4: Bataan | I4: Cavite | J4: Occidental_Mindoro | K4: Camarines_Norte | L4: Antique | M4: Negros_Oriental | N4: Cebu | O4: Eastern_Samar | P4: Zamboanga_del_Sur | Q4: Camiguin | R4: Davao_del_Sur | S4: South_Cotabato | T4: Agusan_del_Sur
B5: Tawi-Tawi | E5: Benguet | F5: La_Union | G5: Isabela | H5: Bulacan | I5: Laguna | J5: Oriental_Mindoro | K5: Camarines_Sur | L5: Capiz | M5: Siquijor | O5: Leyte | P5: Zamboanga_Sibugay | Q5: Lanao_del_Norte | R5: Davao_Oriental | S5: Sultan_Kudarat | T5: Surigao_del_Norte
B6: Maguindanao_del_Norte | E6: Ifugao | F6: Pangasinan | G6: Nueva_Vizcaya | H6: Nueva_Ecija | I6: Quezon | J6: Palawan | K6: Catanduanes | L6: Iloilo | O6: Northern_Samar | P6: Basilan | Q6: Misamis_Occidental | R6: Davao_de_Oro | S6: Sarangani | T6: Surigao_del_Sur
B7: Maguindanao_del_Sur | E7: Kalinga | G7: Quirino | H7: Pampanga | I7: Rizal | J7: Romblon | K7: Masbate | L7: Guimaras | O7: Samar | P7: Sulu | Q7: Misamis_Oriental | R7: Davao_Occidental | T7: Dinagat_Islands
E8: Mountain_Province | H8: Tarlac | K8: Sorsogon | N8: Biliran | O8: Southern_Leyte
H9: Zambales
A10: PROVINCES
A11: Province_PLGU | B11: Metro_Manila | C11: Abra | D11: Apayao | E11: Benguet | F11: Ifugao | G11: Kalinga | H11: Mountain_Province | I11: Ilocos_Norte | J11: Ilocos_Sur | K11: La_Union | L11: Pangasinan | M11: Batanes | N11: Cagayan | O11: Isabela | P11: Nueva_Vizcaya | Q11: Quirino | R11: Bataan | S11: Bulacan | T11: Nueva_Ecija | U11: Pampanga | V11: Tarlac | W11: Zambales | X11: Aurora | Y11: Batangas | Z11: Cavite | AA11: Laguna | AB11: Quezon | AC11: Rizal | AD11: Marinduque | AE11: Occidental_Mindoro | AF11: Oriental_Mindoro | AG11: Palawan | AH11: Romblon | AI11: Albay | AJ11: Camarines_Norte | AK11: Camarines_Sur | AL11: Catanduanes | AM11: Masbate | AN11: Sorsogon | AO11: Aklan | AP11: Antique | AQ11: Capiz | AR11: Iloilo | AS11: Guimaras | AT11: Negros_Occidental | AU11: Negros_Oriental | AV11: Siquijor | AW11: Bohol | AX11: Cebu | AY11: Eastern_Samar | AZ11: Leyte | BA11: Northern_Samar | BB11: Samar | BC11: Southern_Leyte | BD11: Biliran | BE11: Zamboanga_del_Norte | BF11: Zamboanga_del_Sur | BG11: Zamboanga_Sibugay | BH11: Basilan | BI11: Bukidnon | BJ11: Camiguin | BK11: Lanao_del_Norte | BL11: Misamis_Occidental | BM11: Misamis_Oriental | BN11: Davao_del_Norte | BO11: Davao_del_Sur | BP11: Davao_Oriental | BQ11: Davao_de_Oro | BR11: Davao_Occidental | BS11: Cotabato | BT11: South_Cotabato | BU11: Sultan_Kudarat | BV11: Sarangani | BW11: Agusan_del_Norte | BX11: Agusan_del_Sur | BY11: Surigao_del_Norte | BZ11: Surigao_del_Sur | CA11: Dinagat_Islands | CB11: Sulu
A12: Abra | B12: City_of_Caloocan | C12: Bangued | D12: Calanasan | E12: Atok | F12: Aguinaldo | G12: Balbalan | H12: Barlig | I12: Adams | J12: Alilem | K12: Agoo | L12: Agno | M12: Basco | N12: Abulug | O12: Alicia | P12: Alfonso_Castañeda | Q12: Aglipay | R12: Abucay | S12: Angat | T12: Aliaga | U12: Apalit | V12: Anao | W12: Botolan | X12: Baler | Y12: Agoncillo | Z12: Alfonso | AA12: Alaminos | AB12: Agdangan | AC12: Angono | AD12: Boac | AE12: Abra_De_Ilog | AF12: Baco | AG12: Aborlan | AH12: Alcantara | AI12: Bacacay | AJ12: Basud | AK12: Baao | AL12: Bagamanoc | AM12: Aroroy | AN12: Barcelona | AO12: Altavas | AP12: Anini-Y | AQ12: City_of_Roxas | AR12: Ajuy | AS12: Buenavista | AT12: Binalbagan | AU12: Amlan | AV12: Enrique_Villanueva | AW12: Alburquerque | AX12: Alcantara | AY12: Arteche | AZ12: Abuyog | BA12: Allen | BB12: Almagro | BC12: Anahawan | BD12: Almeria | BE12: Baliguian | BF12: Aurora | BG12: Alicia | BH12: City_of_Isabela | BI12: Baungon | BJ12: Catarman | BK12: Bacolod | BL12: Aloran | BM12: Alubijid | BN12: Asuncion | BO12: Bansalan | BP12: Baganga | BQ12: Compostela | BR12: Don_Marcelino | BS12: Alamada | BT12: Banga | BU12: Bagumbayan | BV12: Alabel | BW12: Buenavista | BX12: Bunawan | BY12: Alegria | BZ12: Barobo | CA12: Basilisa | CB12: Hadji Panglima Tahil
A13: Agusan_del_Norte | B13: City_of_Las_Piñas | C13: Boliney | D13: Conner | E13: Bakun | F13: Alfonso_Lista | G13: City_of_Tabuk | H13: Bauko | I13: Bacarra | J13: Banayoyo | K13: Aringay | L13: Aguilar | M13: Itbayat | N13: Alcala | O13: Angadanan | P13: Ambaguio | Q13: Cabarroguis | R13: Bagac | S13: Balagtas | T13: Bongabon | U13: Arayat | V13: Bamban | W13: Cabangan | X13: Casiguran | Y13: Alitagtag | Z13: Amadeo | AA13: Bay | AB13: Alabat | AC13: Baras | AD13: Buenavista | AE13: Calintaan | AF13: Bansud | AG13: Agutaya | AH13: Banton | AI13: Camalig | AJ13: Capalonga | AK13: Balatan | AL13: Baras | AM13: Baleno | AN13: Bulan | AO13: Balete | AP13: Antique | AQ13: Cuartero | AR13: Alimodian | AS13: Jordan | AT13: Calatrava | AU13: Ayungon | AV13: Larena | AW13: Alicia | AX13: Alcoy | AY13: Balangiga | AZ13: Alangalang | BA13: Biri | BB13: Basey | BC13: Bontoc | BD13: Biliran | BE13: City_of_Dapitan | BF13: Bayog | BG13: Buug | BI13: Cabanglasan | BJ13: Guinsiliban | BK13: Baloi | BL13: Baliangao | BM13: Balingasag | BN13: Braulio_E_Dujali | BO13: City_of_Davao | BP13: Banaybanay | BQ13: Laak | BR13: Jose_Abad_Santos | BS13: Aleosan | BT13: City_of_General_Santos | BU13: City_of_Tacurong | BV13: Glan | BW13: Carmen_ADN | BX13: City_of_Bayugan | BY13: Bacuag | BZ13: Bayabas | CA13: Cagdianao | CB13: Indanan
A14: Agusan_del_Sur | B14: City_of_Makati | C14: Bucay | D14: Flora | E14: Bokod | F14: Asipulo | G14: Lubuagan | H14: Besao | I14: Badoc | J14: Bantay | K14: Bacnotan | L14: Alcala | M14: Ivana | N14: Allacapan | O14: Aurora | P14: Aritao | Q14: Diffun | R14: City_of_Balanga | S14: Bocaue | T14: Cabiao | U14: Bacolor | V14: Camiling | W14: Candelaria | X14: Dilasag | Y14: Balayan | Z14: City_of_Bacoor | AA14: Calauan | AB14: Atimonan | AC14: Binangonan | AD14: Gasan | AE14: Looc | AF14: Bongabong | AG14: Araceli | AH14: Cajidiocan | AI14: City_of_Legazpi | AJ14: Daet | AK14: Bato | AL14: Bato_Catanduanes | AM14: Balud | AN14: Bulusan | AO14: Banga | AP14: Barbaza | AQ14: Dao | AR14: Anilao | AS14: Nueva_Valencia | AT14: Candoni | AU14: Bacong | AV14: Lazi | AW14: Anda | AX14: Alegria | AY14: Balangkayan | AZ14: Albuera | BA14: Bobon | BB14: Calbiga | BC14: City_of_Maasin | BD14: Cabucgayan | BE14: City_of_Dipolog | BF14: City_of_Pagadian | BG14: Diplahan | BI14: City_of_Malaybalay | BJ14: Mahinog | BK14: Baroy | BL14: Bonifacio | BM14: Balingoan | BN14: Carmen | BO14: City_of_Digos | BP14: Boston | BQ14: Mabini | BR14: Malita_ | BS14: Antipas | BT14: City_of_Koronadal | BU14: Columbio | BV14: Kiamba | BW14: City_of_Butuan | BX14: Esperanza | BY14: Burgos | BZ14: Cagwait | CA14: Dinagat | CB14: Jolo
A15: Aklan | B15: City_of_Malabon | C15: Bucloc | D15: Kabugao | E15: Buguias | F15: Banaue | G15: Pasil | H15: Bontoc | I15: Bangui | J15: Burgos_Ilocos-Sur | K15: Bagulin | L15: Anda | M15: Mahatao | N15: Amulung | O15: Benito_Soliven | P15: Bagabag | Q15: Maddela | R15: Dinalupihan | S15: Bulacan | T15: Carranglan | U15: Candaba | V15: Capas | W15: Castillejos | X15: Dinalungan | Y15: Balete | Z15: City_of_Carmona | AA15: Cavinti | AB15: Buenavista | AC15: Cainta | AD15: Mogpog | AE15: Lubang | AF15: Bulalacao | AG15: Balabac | AH15: Calatrava | AI15: City_of_Ligao | AJ15: Jose_Panganiban | AK15: Bombon | AL15: Caramoran | AM15: Batuan | AN15: Casiguran | AO15: Batan | AP15: Belison | AQ15: Dumalag | AR15: Badiangan | AS15: San_Lorenzo | AT15: Cauayan | AU15: Basay | AV15: Maria | AW15: Antequera | AX15: Aloguinsan | AY15: Can-Avid | AZ15: Babatngon | BA15: Capul | BB15: City_of_Calbayog | BC15: Hinunangan | BD15: Caibiran | BE15: Godod | BF15: City_of_Zamboanga | BG15: Imelda | BI15: City_of_Valencia | BJ15: Mambajao | BK15: City_of_Iligan | BL15: Calamba | BM15: Binuangan | BN15: City_of_Panabo | BO15: Hagonoy | BP15: Caraga | BQ15: Maco | BR15: Santa_Maria | BS15: Arakan | BT15: Lake_Sebu | BU15: Esperanza | BV15: Maasim | BW15: City_of_Cabadbaran | BX15: La_Paz | BY15: City_of_Surigao | BZ15: Cantilan | CA15: Libjo | CB15: Kalingalan Caluang
A16: Albay | B16: City_of_Mandaluyong | C16: Daguioman | D16: Luna | E16: City_of_Baguio | F16: Hingyon | G16: Pinukpuk | H16: Natonin | I16: Banna | J16: Cabugao | K16: Balaoan | L16: Asingan | M16: Sabtang | N16: Aparri | O16: Burgos | P16: Bambang | Q16: Nagtipunan | R16: Hermosa | S16: Bustos | T16: City_of_Cabanatuan | U16: City_of_Angeles | V16: City_of_Tarlac | W16: City_of_Olongapo | X16: Dingalan | Y16: Batangas_City | Z16: City_of_Cavite | AA16: City_of_Biñan | AB16: Burdeos | AC16: Cardona | AD16: Santa_Cruz | AE16: Magsaysay | AF16: City_of_Calapan | AG16: Bataraza | AH16: Concepcion | AI16: City_of_Tabaco | AJ16: Labo | AK16: Buhi | AL16: Gigmoto | AM16: Cataingan | AN16: Castilla | AO16: Buruanga | AP16: Bugasong | AQ16: Dumarao | AR16: Balasan | AS16: Sibunag | AT16: City of | AU16: Bindoy | AV16: San_Juan | AW16: Baclayon | AX16: Argao | AY16: City_of_Borongan | AZ16: Barugo | BA16: Catarman | BB16: City_of_Catbalogan | BC16: Hinundayan | BD16: Culaba | BE16: Gutalac | BF16: Dimataling | BG16: Ipil | BI16: Damulog | BJ16: Sagay | BK16: Kapatagan | BL16: City_of_Oroquieta | BM16: City_of_Cagayan_De_Oro | BN16: City_of_Tagum | BO16: Kiblawan | BP16: Cateel | BQ16: Maragusan | BR16: Sarangani | BS16: Banisilan | BT16: Norala | BU16: Isulan | BV16: Maitum | BW16: Jabonga | BX16: Loreto_ADS | BY16: Claver | BZ16: Carmen | CA16: Loreto | CB16: Lugus
A17: Antique | B17: City_of_Manila | C17: Danglas | D17: Pudtol | E17: Itogon | F17: Hungduan | G17: Rizal | H17: Paracelis | I17: Burgos | J17: Caoayan | K17: Bangar | L17: Balungao | M17: Uyugan | N17: Baggao | O17: Cabagan | P17: Bayombong | Q17: Saguday | R17: Limay | S17: Calumpit | T17: City_of_Gapan | U17: City_of_San_Fernando | V17: Concepcion | W17: Iba | X17: Dipaculao | Y17: Bauan | Z17: City_of_Dasmariñas | AA17: City_of_Cabuyao | AB17: Calauag | AC17: City_of_Antipolo | AD17: Torrijos | AE17: Mamburao | AF17: Gloria | AG17: Brooke's_Point | AH17: Corcuera | AI17: Daraga | AJ17: Mercedes | AK17: Bula | AL17: Pandan | AM17: Cawayan | AN17: City_of_Sorsogon | AO17: Ibajay | AP17: Caluya | AQ17: Ivisan | AR17: Banate | AT17: City_of_Bacolod | AU17: City_of_Bais | AV17: Siquijor | AW17: Balilihan | AX17: Asturias | AY17: Dolores | AZ17: Bato | BA17: Catubig | BB17: Daram | BC17: Libagon | BD17: Kawayan | BE17: Jose_Dalman | BF17: Dinas | BG17: Kabasalan | BI17: Dangcagan | BK17: Kauswagan | BL17: City_of_Ozamiz | BM17: City_of_El_Salvador | BN17: Island_Garden_City_of_Samal | BO17: Magsaysay | BP17: City_of_Mati | BQ17: Mawab | BS17: Carmen | BT17: Polomolok | BU17: Kalamansig | BV17: Malapatan | BW17: Kitcharao | BX17: Prosperidad | BY17: Dapa | BZ17: Carrascal | CA17: San_Jose | CB17: Luuk
A18: Apayao | B18: City_of_Marikina | C18: Dolores | D18: Santa_Marcela | E18: Kabayan | F18: Kiangan | G18: Tanudan | H18: Sabangan | I18: Carasi | J18: Cervantes | K18: Bauang | L18: Bani | N18: Ballesteros | O18: Cabatuan | P18: Diadi | R18: Mariveles | S18: City_of_Baliwag | T18: City_of_Palayan | U18: Floridablanca | V18: Gerona | W18: Masinloc | X18: Maria_Aurora | Y18: Calatagan | Z18: City_of_General_Trias | AA18: City_of_Calamba | AB18: Candelaria | AC18: Jala-Jala | AE18: Paluan | AF18: Mansalay | AG18: Busuanga | AH18: Ferrol | AI18: Guinobatan | AJ18: Paracale | AK18: Cabusao | AL18: Panganiban | AM18: City_of_Masbate | AN18: Donsol | AO18: Kalibo | AP18: Culasi | AQ18: Jamindan | AR18: Barotac_Nuevo | AT18: City_of_Bago | AU18: City_of_Bayawan | AW18: Batuan | AX18: Badian | AY18: General_Macarthur | AZ18: Burauen | BA18: Gamay | BB18: Gandara | BC18: Liloan | BD18: Maripipi | BE18: Kalawit | BF18: Dumalinao | BG18: Mabuhay | BI18: Don_Carlos | BK18: Kolambugan | BL18: City_of_Tangub | BM18: City_of_Gingoog | BN18: Kapalong | BO18: Malalag | BP18: Governor_Generoso | BQ18: Monkayo | BS18: City_of_Kidapawan | BT18: Santo_Niño | BU18: Lambayong | BV18: Malungon | BW18: Las_Nieves | BX18: Rosario | BY18: Del_Carmen | BZ18: City_of_Bislig | CA18: Tubajon | CB18: Maimbung
A19: Aurora | B19: City_of_Muntinlupa | C19: La_Paz | E19: Kapangan | F19: Lagawe | G19: Tinglayan | H19: Sadanga | I19: City_of_Batac | J19: City_of_Candon | K19: Burgos_La-Union | L19: Basista | N19: Buguey | O19: City_of_Cauayan | P19: Dupax_del_Norte | R19: Morong | S19: City_of_Malolos | T19: Cuyapo | U19: Guagua | V19: La_Paz | W19: Palauig | X19: San_Luis | Y19: City_of_Calaca | Z19: City_of_Imus | AA19: City_of_San_Pablo | AB19: Catanauan | AC19: Morong | AE19: Rizal | AF19: Naujan | AG19: Cagayancillo | AH19: Looc_Romblon | AI19: Jovellar | AJ19: San_Lorenzo_Ruiz | AK19: Calabanga | AL19: San_Andres | AM19: Claveria | AN19: Gubat | AO19: Lezo | AP19: Hamtic | AQ19: Ma-Ayon | AR19: Barotac_Viejo | AT19: City_of_Cadiz | AU19: City_of_Canlaon | AW19: Bien_Unido | AX19: Balamban | AY19: Giporlos | AZ19: Calubian | BA19: Laoang | BB19: Hinabangan | BC19: Limasawa | BD19: Naval | BE19: Katipunan | BF19: Dumingag | BG19: Malangas | BI19: Impasug-ong | BK19: Lala | BL19: Clarin | BM19: Claveria | BN19: New_Corella | BO19: Matanao | BP19: Lupon | BQ19: Montevista | BS19: Kabacan | BT19: Surallah | BU19: Lebak | BW19: Magallanes | BX19: San_Francisco | BY19: General_Luna | BZ19: City_of_Tandag | CB19: Old Panamao
A20: Basilan | B20: City_of_Navotas | C20: Lacub | E20: Kibungan | F20: Lamut | H20: Sagada | I20: City_of_Laoag | J20: City_of_Vigan | K20: Caba | L20: Bautista | N20: Calayan | O20: City_of_Ilagan | P20: Dupax_del_Sur | R20: Orani | S20: City_of_Meycauayan | T20: Gabaldon | U20: Lubao | V20: Mayantoc | W20: San_Antonio | Y20: City_of_Lipa | Z20: City_of_Tagaytay | AA20: City_of_San_Pedro | AB20: City_of_Lucena | AC20: Pililla | AE20: Sablayan | AF20: Pinamalayan | AG20: City_of_Puerto_Princesa | AH20: Magdiwang | AI20: Libon | AJ20: San_Vicente | AK20: Camaligan | AL20: San_Miguel | AM20: Dimasalang | AN20: Irosin | AO20: Libacao | AP20: Laua-An | AQ20: Mambusao | AR20: Batad | AT20: City_of_Escalante | AU20: City_of_Dumaguete | AW20: Bilar | AX20: Bantayan | AY20: Guiuan | AZ20: Capoocan | BA20: Lapinig | BB20: Jiabong | BC20: Macrohon | BE20: La_Libertad | BF20: Guipos | BG20: Naga | BI20: Kadingilan | BK20: Linamon | BL20: Concepcion | BM20: Gitagum | BN20: San_Isidro_DDN | BO20: Padada | BP20: Manay | BQ20: Nabunturan | BS20: Libungan | BT20: Tampakan | BU20: Lutayan | BW20: Nasipit | BX20: San_Luis | BY20: Gigaquit | BZ20: Cortes | CB20: Omar
A21: Bataan | B21: City_of_Parañaque | C21: Lagangilang | E21: La_Trinidad | F21: Mayoyao | H21: Tadian | I21: Currimao | J21: Galimuyod | K21: City_of_San_Fernando | L21: Bayambang | N21: Camalaniugan | O21: City_of_Santiago | P21: Kasibu | R21: Orion | S21: City_of_San_Jose_Del_Monte | T21: General_Mamerto_Natividad | U21: Mabalacat_City | V21: Moncada | W21: San_Felipe | Y21: City_of_Sto_Tomas | Z21: City_of_Trece_Martires | AA21: City_of_Santa_Rosa | AB21: City_of_Tayabas | AC21: Rodriguez | AE21: San_Jose | AF21: Pola | AG21: Coron | AH21: Odiongan | AI21: Malilipot | AJ21: Santa_Elena | AK21: Canaman | AL21: Viga | AM21: Esperanza | AN21: Juban | AO21: Madalag | AP21: Libertad | AQ21: Panay | AR21: Bingawan | AT21: City_of_Himamaylan | AU21: City_of_Guihulngan | AW21: Buenavista | AX21: Barili | AY21: Hernani | AZ21: Carigara | BA21: Las_Navas | BB21: Marabut | BC21: Malitbog | BE21: Labason | BF21: Josefina | BG21: Olutanga | BI21: Kalilangan | BK21: Magsaysay | BL21: Don_Victoriano_Chiongbian | BM21: Initao | BN21: Santo_Tomas | BO21: Santa_Cruz | BP21: San_Isidro | BQ21: New_Bataan | BS21: Magpet | BT21: Tantangan | BU21: Palimbang | BW21: Remedios_T_Romualdez | BX21: Santa_Josefa | BY21: Mainit | BZ21: Hinatuan | CB21: Pandami
A22: Batanes | B22: Pasay_City | C22: Lagayan | E22: Mankayan | F22: Tinoc | I22: Dingras | J22: Gregorio_del_Pilar | K22: Luna | L22: Binalonan | N22: Claveria | O22: Cordon | P22: Kayapa | R22: Pilar | S22: Doña_Remedios_Trinidad | T22: General_Tinio | U22: Macabebe | V22: Paniqui | W22: San_Marcelino | Y22: City_of_Tanauan | Z22: Gen._Mariano_Alvarez | AA22: Famy | AB22: Dolores | AC22: San_Mateo | AE22: Santa_Cruz | AF22: Puerto_Galera | AG22: Culion | AH22: Romblon | AI22: Malinao | AJ22: Talisay | AK22: Caramoan | AL22: Virac | AM22: Mandaon | AN22: Magallanes | AO22: Makato | AP22: Pandan | AQ22: Panitan | AR22: Cabatuan | AT22: City_of_Kabankalan | AU22: City_of_Tanjay | AW22: Calape | AX22: Boljoon | AY22: Jipapad | AZ22: City_of_Baybay | BA22: Lavezares | BB22: Matuguinao | BC22: Padre_Burgos | BE22: Leon_T_Postigo | BF22: Kumalarang | BG22: Payao | BI22: Kibawe | BK22: Maigo | BL22: Jimenez | BM22: Jasaan | BN22: Talaingod | BO22: Sulop | BP22: Tarragona | BQ22: Pantukan | BS22: Makilala | BT22: T'Boli | BU22: President_Quirino | BW22: Santiago | BX22: Sibagat | BY22: Malimono | BZ22: Lanuza | CB22: Panglima Estino (New Panamao)
A23: Batangas | B23: City_of_Pasig | C23: Langiden | E23: Sablan | I23: Dumalneg | J23: Lidlidda | K23: Naguilian | L23: Binmaley | N23: Enrile | O23: Delfin_Albano | P23: Quezon | R23: Samal | S23: Guiguinto | T23: Guimba | U23: Magalang | V23: Pura | W23: San_Narciso | Y23: Cuenca | Z23: General_Emilio_Aguinaldo | AA23: Kalayaan | AB23: General_Luna | AC23: Tanay | AF23: Roxas | AG23: Cuyo | AH23: San_Agustin | AI23: Manito | AJ23: Vinzons | AK23: City_of_Iriga | AM23: Milagros | AN23: Matnog | AO23: Malay | AP23: Patnongon | AQ23: Pilar | AR23: Calinog | AT23: City_of_La_Carlota | AU23: Dauin | AW23: Candijay | AX23: Borbon | AY23: Lawaan | AZ23: City_of_Tacloban | BA23: Lope_De_Vega | BB23: Motiong | BC23: Pintuyan | BE23: Liloy | BF23: Labangan | BG23: Roseller_Lim | BI23: Kitaotao | BK23: Matungao | BL23: Lopez_Jaena | BM23: Kinoguitan | BS23: Matalam | BT23: Tupi | BU23: Sen_Ninoy_Aquino | BW23: Tubay | BX23: Talacogon | BY23: Pilar | BZ23: Lianga | CB23: Pangutaran
A24: Benguet | B24: Quezon_City | C24: Licuan-Baay | E24: Tuba | I24: Marcos | J24: Magsingal | K24: Pugo | L24: Bolinao | N24: Gattaran | O24: Dinapigue | P24: Santa_Fe | S24: Hagonoy | T24: Jaen | U24: Masantol | V24: Ramos | W24: Santa_Cruz | Y24: Ibaan | Z24: Indang | AA24: Liliw | AB24: General_Nakar | AC24: Taytay | AF24: San _Teodoro | AG24: Dumaran | AH24: San_Andres | AI24: Oas | AK24: City_of_Naga | AM24: Mobo | AN24: Pilar | AO24: Malinao | AP24: San_Jose | AQ24: Pontevedra | AR24: Carles | AT24: City_of_San_Carlos | AU24: Jimalalud | AW24: Carmen | AX24: Carmen_Cebu | AY24: Llorente | AZ24: Dagami | BA24: Mapanas | BB24: Pagsanghan | BC24: Saint_Bernard | BE24: Manukan | BF24: Lakewood | BG24: Siay | BI24: Lantapan | BK24: Munai | BL24: Panaon | BM24: Lagonglong | BS24: Midsayap | BX24: Trento | BY24: Placer | BZ24: Lingig | CB24: Parang
A25: Biliran | B25: City_of_San_Juan | C25: Luba | E25: Tublay | I25: Nueva_Era | J25: Nagbukel | K25: Rosario | L25: Bugallon | N25: Gonzaga | O25: Divilacan | P25: Solano | S25: Marilao | T25: Laur | U25: Mexico | V25: San_Clemente | W25: Subic | Y25: Laurel | Z25: Kawit | AA25: Los_Baños | AB25: Guinayangan | AC25: Teresa | AF25: Socorro | AG25: El_Nido | AH25: San_Fernando | AI25: Pio_Duran | AK25: Del_Gallego | AM25: Monreal | AN25: Prieto_Diaz | AO25: Nabas | AP25: San_Remigio | AQ25: President_Roxas | AR25: City_of_Iloilo | AT25: City_of_Silay | AU25: La_Libertad | AW25: Catigbian | AX25: Catmon | AY25: Maslog | AZ25: Dulag | BA25: Mondragon | BB25: Paranas | BC25: San_Francisco | BE25: Mutia | BF25: Lapuyan | BG25: Talusan | BI25: Libona | BK25: Nunungan | BL25: Plaridel | BM25: Laguindingan | BS25: M'Lang | BX25: Veruela | BY25: San_Benito | BZ25: Madrid | CB25: Pata
A26: Bohol | B26: City_of_Taguig | C26: Malibcong | I26: Pagudpud | J26: Narvacan | K26: San_Gabriel | L26: Burgos_Pangasinan | N26: Iguig | O26: Echague | P26: Villaverde | S26: Norzagaray | T26: Licab | U26: Minalin | V26: San_Jose | Y26: Lemery | Z26: Magallanes | AA26: Luisiana | AB26: Gumaca | AF26: Victoria | AG26: Kalayaan | AH26: San_Jose | AI26: Polangui | AK26: Gainza | AM26: Palanas | AN26: Santa_Magdalena | AO26: New_Washington | AP26: Sebaste | AQ26: Sapi-An | AR26: City_of_Passi | AT26: City_of_Sipalay | AU26: Mabinay | AW26: City_of_Tagbilaran | AX26: City_of_Bogo | AY26: Maydolong | AZ26: Hilongos | BA26: Palapag | BB26: Pinabacdao | BC26: San_Juan | BE26: Piñan | BF26: Mahayag | BG26: Titay | BI26: Malitbog | BK26: Pantao_Ragat | BL26: Sapang_Dalaga | BM26: Libertad | BS26: Pigkawayan | BY26: San_Francisco | BZ26: Marihatag | CB26: Patikul
A27: Bukidnon | B27: City_of_Valenzuela | C27: Manabo | I27: Paoay | J27: Quirino | K27: San_Juan | L27: Calasiao | N27: Lal-Lo | O27: Gamu | S27: Obando | T27: Llanera | U27: Porac | V27: San_Manuel | Y27: Lian | Z27: Maragondon | AA27: Lumban | AB27: Infanta | AG27: Linapacan | AH27: Santa_Fe | AI27: Rapu-Rapu | AK27: Garchitorena | AM27: Pio_V_Corpus | AO27: Numancia | AP27: Sibalom | AQ27: Sigma | AR27: Concepcion | AT27: City_of_Talisay | AU27: Manjuyod | AW27: Clarin | AX27: City_of_Carcar | AY27: Mercedes | AZ27: Hindang | BA27: Pambujan | BB27: San_Jorge | BC27: San_Ricardo | BE27: Polanco | BF27: Margosatubig | BG27: Tungawan | BI27: Manolo_Fortich | BK27: Pantar | BL27: Sinacaban | BM27: Lugait | BS27: Pikit | BY27: San_Isidro | BZ27: San_Agustin | CB27: Siasi
A28: Bulacan | B28: Pateros | C28: Peñarrubia | I28: Pasuquin | J28: Salcedo | K28: Santo_Tomas | L28: City_of_Alaminos | N28: Lasam | O28: Jones | S28: Pandi | T28: Lupao | U28: San_Luis | V28: Santa_Ignacia | Y28: Lobo | Z28: Mendez | AA28: Mabitac | AB28: Jomalig | AG28: Magsaysay | AH28: Santa_Maria | AI28: Santo_Domingo | AK28: Goa | AM28: Placer | AO28: Tangalan | AP28: Tibiao | AQ28: Tapaz | AR28: Dingle | AT28: City_of_Victorias | AU28: Pamplona | AW28: Corella | AX28: City_of_Cebu | AY28: Oras | AZ28: Inopacan | BA28: Rosario | BB28: San_Jose_De_Buan | BC28: Silago | BE28: Pres_Manuel_A_Roxas | BF28: Midsalip | BI28: Maramag | BK28: Poona_Piagapo | BL28: Tudela | BM28: Magsaysay | BS28: President_Roxas | BY28: Santa_Monica | BZ28: San_Miguel | CB28: Talipao
A29: Cagayan | C29: Pidigan | I29: Piddig | J29: San_Emilio | K29: Santol | L29: City_of_Dagupan | N29: Pamplona | O29: Luna | S29: Paombong | T29: Nampicuan | U29: San_Simon | V29: Victoria | Y29: Mabini | Z29: Naic | AA29: Magdalena | AB29: Lopez | AG29: Narra | AI29: Tiwi | AK29: Lagonoy | AM29: San_Fernando_Masbate | AP29: Tobias_Fornier | AR29: Dueñas | AT29: Enrique_B_Magalona | AU29: San_Jose | AW29: Cortes | AX29: City_of_Lapu-Lapu | AY29: Quinapondan | AZ29: Isabel | BA29: San_Antonio | BB29: San_Sebastian | BC29: Sogod | BE29: Rizal | BF29: Molave | BI29: Pangantucan | BK29: Salvador | BM29: Manticao | BS29: Tulunan | BY29: Sison | BZ29: Tagbina | CB29: Tapul
A30: Camarines_Norte | C30: Pilar | I30: Pinili | J30: San_Esteban | K30: Sudipen | L30: City_of_San_Carlos | N30: Peñablanca | O30: Maconacon | S30: Plaridel | T30: Pantabangan | U30: Santa_Ana | Y30: Malvar | Z30: Noveleta | AA30: Majayjay | AB30: Lucban | AG30: Quezon | AK30: Libmanan | AM30: San_Jacinto | AP30: Valderrama | AR30: Dumangas | AT30: Hinigaran | AU30: Santa_Catalina | AW30: Dagohoy | AX30: City_of_Mandaue | AY30: Salcedo | AZ30: Jaro | BA30: San_Isidro | BB30: Santa_Margarita | BC30: Tomas_Oppus | BE30: Salug | BF30: Pitogo | BI30: Quezon | BK30: Sapad | BM30: Medina | BY30: Socorro | BZ30: Tago | CB30: Tungkil (Banguingui)
A31: Camarines_Sur | C31: Sallapadan | I31: San_Nicolas | J31: San_Ildefonso | K31: Tubao | L31: City_of_Urdaneta | N31: Piat | O31: Mallig | S31: Pulilan | T31: Peñaranda | U31: Santa_Rita | Y31: Mataas_na_Kahoy | Z31: Rosario | AA31: Nagcarlan | AB31: Macalelon | AG31: Rizal | AK31: Lupi | AM31: San_Pascual | AR31: Estancia | AT31: Hinoba-an | AU31: Siaton | AW31: Danao | AX31: City_of_Naga | AY31: San_Julian | AZ31: Javier | BA31: San_Jose | BB31: Santa_Rita | BE31: Sergio_Osmeña_Sr. | BF31: Ramon_Magsaysay | BI31: San_Fernando | BK31: Sultan_Naga_Dimaporo | BM31: Naawan | BY31: Tagana-An
A32: Camiguin | C32: San_Isidro | I32: Sarrat | J32: San_Juan | L32: Dasol | N32: Rizal | O32: Naguilian | S32: San_Ildefonso | T32: Quezon | U32: Sasmuan | Y32: Nasugbu | Z32: Silang | AA32: Paete | AB32: Mauban | AG32: Roxas | AK32: Magarao | AM32: Uson | AR32: Guimbal | AT32: Ilog | AU32: Sibulan | AW32: Dauis | AX32: City_of_Talisay | AY32: San_Policarpo | AZ32: Julita | BA32: San_Roque | BB32: Santo_Niño | BE32: Siayan | BF32: San_Miguel | BI32: Sumilao | BK32: Tagoloan_LDN | BM32: Opol | BY32: Tubod
A33: Capiz | C33: San_Juan | I33: Solsona | J33: San_Vicente | L33: Infanta | N33: Sanchez-Mira | O33: Palanan | S33: San_Miguel | T33: Rizal | U33: Sto._Tomas | Y33: Padre_Garcia | Z33: Tanza | AA33: Pagsanjan | AB33: Mulanay | AG33: San_Vicente | AK33: Milaor | AR33: Igbaras | AT33: Isabela | AU33: Tayasan | AW33: Dimiao | AX33: City_of_Toledo | AY33: Sulat | AZ33: Kananga | BA33: San_Vicente | BB33: Tagapul-An | BE33: Sibuco | BF33: San_Pablo | BI33: Talakag | BK33: Tangcal | BM33: Salay
A34: Catanduanes | C34: San_Quintin | I34: Vintar | J34: Santa | L34: Labrador | N34: Santa_Ana | O34: Quezon | S34: San_Rafael | T34: San_Antonio | Y34: Rosario | Z34: Ternate | AA34: Pakil | AB34: Padre_Burgos | AG34: Sofronio_Española | AK34: Minalabac | AR34: Janiuay | AT34: La_Castellana | AU34: Valencia | AW34: Duero | AX34: Compostela | AY34: Taft | AZ34: La_Paz | BA34: Silvino_Lobos | BB34: Talalora | BE34: Sibutad | BF34: Sominot | BK34: Tubod | BM34: Sugbongcogon
A35: Cavite | C35: Tayum | J35: Santa_Catalina | L35: Laoac | N35: Santa_Praxedes | O35: Quirino | S35: Santa_Maria | T35: San_Isidro | Y35: San_Jose | AA35: Pangil | AB35: Pagbilao | AG35: Taytay | AK35: Nabua | AR35: Lambunao | AT35: Manapla | AU35: Vallehermoso | AW35: Garcia_Hernandez | AX35: Consolacion | AZ35: Leyte | BA35: Victoria | BB35: Tarangnan | BE35: Sindangan | BF35: Tabina | BM35: Tagoloan
A36: Cebu | C36: Tineg | J36: Santa_Cruz | L36: Lingayen | N36: Santa_Teresita | O36: Ramon | T36: San_Jose_City | Y36: San_Juan | AA36: Pila | AB36: Panukulan | AK36: Ocampo | AR36: Leganes | AT36: Moises_Padilla | AU36: Zamboanguita | AW36: Getafe | AX36: Cordova | AZ36: Macarthur | BB36: Villareal | BE36: Siocon | BF36: Tambulig | BM36: Talisayan
A37: Cotabato | C37: Tubo | J37: Santa_Lucia | L37: Mabini | N37: Santo_Niño | O37: Reina_Mercedes | T37: San_Leonardo | Y37: San_Luis | AA37: Rizal | AB37: Patnanungan | AK37: Pamplona | AR37: Lemery | AT37: Murcia | AW37: Guindulman | AX37: Daanbantayan | AZ37: Mahaplag | BB37: Zumarraga | BE37: Sirawai | BF37: Tigbao | BM37: Villanueva
A38: Davao_de_Oro | C38: Villaviciosa | J38: Santa_Maria | L38: Malasiqui | N38: Solana | O38: Roxas | T38: Santa_Rosa | Y38: San_Nicolas | AA38: Santa_Cruz | AB38: Perez | AK38: Pasacao | AR38: Leon | AT38: Pontevedra | AW38: Inabanga | AX38: Dalaguete | AZ38: Matag-Ob | BE38: Tampilisan | BF38: Tukuran
A39: Davao_del_Norte | J39: Santiago | L39: Manaoag | N39: Tuao | O39: San_Agustin | T39: Santo_Domingo | Y39: San_Pascual | AA39: Santa_Maria | AB39: Pitogo | AK39: Pili | AR39: Maasin | AT39: Pulupandan | AW39: Jagna | AX39: Danao_City | AZ39: Matalom | BF39: Vincenzo_A_Sagun
A40: Davao_del_Sur | J40: Santo_Domingo | L40: Mangaldan | N40: Tuguegarao_City | O40: San_Guillermo | T40: Science_City_of_Muñoz | Y40: Santa_Teresita | AA40: Siniloan | AB40: Plaridel | AK40: Presentacion | AR40: Miagao | AT40: Salvador_Benedicto | AW40: Lila | AX40: Dumanjug | AZ40: Mayorga
...

Sheet Accomplishment 2026
A3: Republic of the Philippines
A4: DEPARTMENT OF HUMAN SETTLEMENTS AND URBAN DEVELOPMENT
A6: DHSUD REGIONAL OFFICE NEGROS ISALAND REGION
A7: ENVIRONMENTAL, LAND USE AND URBAN PLANNING AND DEVELOPMENT DIVISION
A8: 2026 ACCOMPLISHMENT REPORT (As of FEBRUARY)
A10: INDICATORS | E10: TOTAL TARGETS (YEAR) | F10: MONTHLY ACCOMPLISHMENT | R10: 1Q | S10: 2Q | T10: 3Q | U10: 4Q | V10: TOTAL ACCOMP. (YEAR) | W10: REMARKS | X10: LINK TO ANNEX
F11: January | G11: February | H11: March | I11: April | J11: May | K11: June | L11: July | M11: August | N11: September | O11: October | P11: November | Q11: December
A12: OUTCOME INDICATORS
B13: 1 | C13: Formulation of sustainable and resilient human settlements plans
D14: 1.1. Number of LGUs with approved CLUPs within the year | E14: 5 | F14: =COUNTIF('Annex 1.1. Outcome_CLUP'!H14:H1048576,"January") -> 0 | G14: =COUNTIF('Annex 1.1. Outcome_CLUP'!H14:H1048576,"February") -> 0 | H14: =COUNTIF('Annex 1.1. Outcome_CLUP'!H14:H1048576,"March") -> 0 | I14: =COUNTIF('Annex 1.1. Outcome_CLUP'!H14:H1048576,"April") -> 0 | J14: =COUNTIF('Annex 1.1. Outcome_CLUP'!H14:H1048576,"May") -> 0 | K14: =COUNTIF('Annex 1.1. Outcome_CLUP'!H14:H1048576,"June") -> 0 | L14: =COUNTIF('Annex 1.1. Outcome_CLUP'!H14:H1048576,"July") -> 0 | M14: =COUNTIF('Annex 1.1. Outcome_CLUP'!H14:H1048576,"August") -> 0 | N14: =COUNTIF('Annex 1.1. Outcome_CLUP'!H14:H1048576,"September") -> 0 | O14: =COUNTIF('Annex 1.1. Outcome_CLUP'!H14:H1048576,"October") -> 0 | P14: =COUNTIF('Annex 1.1. Outcome_CLUP'!H14:H1048576,"November") -> 0 | Q14: =COUNTIF('Annex 1.1. Outcome_CLUP'!H14:H1048576,"December") -> 0 | R14: =SUM(F14:H14) -> 0 | S14: =SUM(I14:K14) -> 0 | T14: =SUM(L14:N14) -> 0 | U14: =SUM(O14:Q14) -> 0 | V14: =SUM(F14:Q14) -> 0 | X14: Annex 1.1. Outcome_CLUP
D15: 1.1.1 Number of LGUs with CLUPs within the year with integrated or separately prepared CLUP Communications Plan | E15: 5 | F15: =COUNTIF('Annex 1.1.1 Outcome_CommPlan'!$H$14:$H$1048576,"January") -> 0 | G15: =COUNTIF('Annex 1.1.1 Outcome_CommPlan'!$H$14:$H$1048576,"February") -> 0 | H15: =COUNTIF('Annex 1.1.1 Outcome_CommPlan'!$H$14:$H$1048576,"March") -> 0 | I15: =COUNTIF('Annex 1.1.1 Outcome_CommPlan'!$H$14:$H$1048576,"April") -> 0 | J15: =COUNTIF('Annex 1.1.1 Outcome_CommPlan'!$H$14:$H$1048576,"May") -> 0 | K15: =COUNTIF('Annex 1.1.1 Outcome_CommPlan'!$H$14:$H$1048576,"June") -> 0 | L15: =COUNTIF('Annex 1.1.1 Outcome_CommPlan'!$H$14:$H$1048576,"July") -> 0 | M15: =COUNTIF('Annex 1.1.1 Outcome_CommPlan'!$H$14:$H$1048576,"August") -> 0 | N15: =COUNTIF('Annex 1.1.1 Outcome_CommPlan'!$H$14:$H$1048576,"September") -> 0 | O15: =COUNTIF('Annex 1.1.1 Outcome_CommPlan'!$H$14:$H$1048576,"October") -> 0 | P15: =COUNTIF('Annex 1.1.1 Outcome_CommPlan'!$H$14:$H$1048576,"November") -> 0 | Q15: =COUNTIF('Annex 1.1.1 Outcome_CommPlan'!$H$14:$H$1048576,"December") -> 0 | R15: =SUM(F15:H15) -> 0 | S15: =SUM(I15:K15) -> 0 | T15: =SUM(L15:N15) -> 0 | U15: =SUM(O15:Q15) -> 0 | V15: =SUM(F15:Q15) -> 0 | X15: Annex 1.1.1 Outcome_CommPlan'!A1
D16: 1.1.2 Number of LGUs with approved Comprehensive Land Use Plans (CLUPs) within the year with integrated enhanced housing sub-sector (LSP) | E16: 5 | F16: =COUNTIF('Annex 1.1.2 Outcome_Housing'!$H$14:$H$1048576, "January") -> 0 | G16: =COUNTIF('Annex 1.1.2 Outcome_Housing'!$H$14:$H$1048576, "February") -> 0 | H16: =COUNTIF('Annex 1.1.2 Outcome_Housing'!$H$14:$H$1048576, "March") -> 0 | I16: =COUNTIF('Annex 1.1.2 Outcome_Housing'!$H$14:$H$1048576, "April") -> 0 | J16: =COUNTIF('Annex 1.1.2 Outcome_Housing'!$H$14:$H$1048576, "May") -> 0 | K16: =COUNTIF('Annex 1.1.2 Outcome_Housing'!$H$14:$H$1048576, "June") -> 0 | L16: =COUNTIF('Annex 1.1.2 Outcome_Housing'!$H$14:$H$1048576, "July") -> 0 | M16: =COUNTIF('Annex 1.1.2 Outcome_Housing'!$H$14:$H$1048576, "August") -> 0 | N16: =COUNTIF('Annex 1.1.2 Outcome_Housing'!$H$14:$H$1048576, "September") -> 0 | O16: =COUNTIF('Annex 1.1.2 Outcome_Housing'!$H$14:$H$1048576, "October") -> 0 | P16: =COUNTIF('Annex 1.1.2 Outcome_Housing'!$H$14:$H$1048576, "November") -> 0 | Q16: =COUNTIF('Annex 1.1.2 Outcome_Housing'!$H$14:$H$1048576, "December") -> 0 | R16: =SUM(F16:H16) -> 0 | S16: =SUM(I16:K16) -> 0 | T16: =SUM(L16:N16) -> 0 | U16: =SUM(O16:Q16) -> 0 | V16: =SUM(F16:Q16) -> 0 | X16: Annex 1.1.2 Outcome_Housing'!A1
D17: 1.2. Number of provinces with approved PDPFPs/PPFPs within the year | E17: 1 | F17: =COUNTIF('Annex 1.2. Outcome_PDPFP'!$G$14:$G$1048576,"January") -> 0 | G17: =COUNTIF('Annex 1.2. Outcome_PDPFP'!$G$14:$G$1048576,"February") -> 0 | H17: =COUNTIF('Annex 1.2. Outcome_PDPFP'!$G$14:$G$1048576,"March") -> 0 | I17: =COUNTIF('Annex 1.2. Outcome_PDPFP'!$G$14:$G$1048576,"April") -> 0 | J17: =COUNTIF('Annex 1.2. Outcome_PDPFP'!$G$14:$G$1048576,"May") -> 0 | K17: =COUNTIF('Annex 1.2. Outcome_PDPFP'!$G$14:$G$1048576,"June") -> 0 | L17: =COUNTIF('Annex 1.2. Outcome_PDPFP'!$G$14:$G$1048576,"July") -> 0 | M17: =COUNTIF('Annex 1.2. Outcome_PDPFP'!$G$14:$G$1048576,"August") -> 0 | N17: =COUNTIF('Annex 1.2. Outcome_PDPFP'!$G$14:$G$1048576,"September") -> 0 | O17: =COUNTIF('Annex 1.2. Outcome_PDPFP'!$G$14:$G$1048576,"October") -> 0 | P17: =COUNTIF('Annex 1.2. Outcome_PDPFP'!$G$14:$G$1048576,"November") -> 0 | Q17: =COUNTIF('Annex 1.2. Outcome_PDPFP'!$G$14:$G$1048576,"December") -> 0 | R17: =SUM(F17:H17) -> 0 | S17: =SUM(I17:K17) -> 0 | T17: =SUM(L17:N17) -> 0 | U17: =SUM(O17:Q17) -> 0 | V17: =SUM(F17:Q17) -> 0 | X17: Annex 1.2. Outcome_PDPFP'!A1
B18: 2 | C18: Implementation of inclusive, safe, resilient, and sustainable urban development programs
D19: 2.1. Number of LGUs and stakeholders with approved proposals and/or budgeted programs/projects for inclusive, safe, resilient, and sustainable urban development, demonstrating adherence to DHSUD policies, standards, and guidelines | E19: 1 | F19: =COUNTIFS('Annex 2.1. Outcome_UrbanDev'!$K$14:$K$1000,"1st",'Annex 2.1. Outcome_UrbanDev'!$I$14:$I$1000,F11) -> 0 | G19: =COUNTIFS('Annex 2.1. Outcome_UrbanDev'!$K$14:$K$1000,"1st",'Annex 2.1. Outcome_UrbanDev'!$I$14:$I$1000,G11) -> 0 | H19: =COUNTIFS('Annex 2.1. Outcome_UrbanDev'!$K$14:$K$1000,"1st",'Annex 2.1. Outcome_UrbanDev'!$I$14:$I$1000,H11) -> 0 | I19: =COUNTIFS('Annex 2.1. Outcome_UrbanDev'!$K$14:$K$1000,"1st",'Annex 2.1. Outcome_UrbanDev'!$I$14:$I$1000,I11) -> 0 | J19: =COUNTIFS('Annex 2.1. Outcome_UrbanDev'!$K$14:$K$1000,"1st",'Annex 2.1. Outcome_UrbanDev'!$I$14:$I$1000,J11) -> 0 | K19: =COUNTIFS('Annex 2.1. Outcome_UrbanDev'!$K$14:$K$1000,"1st",'Annex 2.1. Outcome_UrbanDev'!$I$14:$I$1000,K11) -> 0 | L19: =COUNTIFS('Annex 2.1. Outcome_UrbanDev'!$K$14:$K$1000,"1st",'Annex 2.1. Outcome_UrbanDev'!$I$14:$I$1000,L11) -> 0 | M19: =COUNTIFS('Annex 2.1. Outcome_UrbanDev'!$K$14:$K$1000,"1st",'Annex 2.1. Outcome_UrbanDev'!$I$14:$I$1000,M11) -> 0 | ... Q19: =COUNTIFS('Annex 2.1. Outcome_UrbanDev'!$K$14:$K$1000,"1st",'Annex 2.1. Outcome_UrbanDev'!$I$14:$I$1000,Q11) -> 0 | R19: =SUM(F19:H19) -> 0 | S19: =SUM(G19:I19) -> 0 | T19: =SUM(H19:J19) -> 0 | U19: =SUM(I19:K19) -> 0 | V19: =SUM(F19:Q19) -> 0 | X19: Annex 2.1. Outcome_UrbanDev'!A1
A20: OUTPUT INDICATORS
B21: Technical Assistance
B22: 1 | C22: Technical assistance on the preparation of CLUPs and ZOs
C23: 1.1. No. of LGUs assisted on the preparation of CLUPs and ZOs (single counting) | E23: 12 | F23: =COUNTIFS('Annex 4.1 TA_CLUP'!$J$18:$J$1005,"1st",'Annex 4.1 TA_CLUP'!$H$18:$H$1005,"January") -> 1 | G23: =COUNTIFS('Annex 4.1 TA_CLUP'!$J$18:$J$1005,"1st",'Annex 4.1 TA_CLUP'!$H$18:$H$1005,"February") -> 3 | H23: =COUNTIFS('Annex 4.1 TA_CLUP'!$J$18:$J$1005,"1st",'Annex 4.1 TA_CLUP'!$H$18:$H$1005,"March") -> 0 | I23: =COUNTIFS('Annex 4.1 TA_CLUP'!$J$18:$J$1005,"1st",'Annex 4.1 TA_CLUP'!$H$18:$H$1005,"April") -> 0 | J23: =COUNTIFS('Annex 4.1 TA_CLUP'!$J$18:$J$1005,"1st",'Annex 4.1 TA_CLUP'!$H$18:$H$1005,"May") -> 0 | K23: =COUNTIFS('Annex 4.1 TA_CLUP'!$J$18:$J$1005,"1st",'Annex 4.1 TA_CLUP'!$H$18:$H$1005,"June") -> 0 | L23: =COUNTIFS('Annex 4.1 TA_CLUP'!$J$18:$J$1005,"1st",'Annex 4.1 TA_CLUP'!$H$18:$H$1005,"July") -> 0 | M23: =COUNTIFS('Annex 4.1 TA_CLUP'!$J$18:$J$1005,"1st",'Annex 4.1 TA_CLUP'!$H$18:$H$1005,"August") -> 0 | N23: =COUNTIFS('Annex 4.1 TA_CLUP'!$J$18:$J$1005,"1st",'Annex 4.1 TA_CLUP'!$H$18:$H$1005,"September") -> 0 | O23: =COUNTIFS('Annex 4.1 TA_CLUP'!$J$18:$J$1005,"1st",'Annex 4.1 TA_CLUP'!$H$18:$H$1005,"October") -> 0 | P23: =COUNTIFS('Annex 4.1 TA_CLUP'!$J$18:$J$1005,"1st",'Annex 4.1 TA_CLUP'!$H$18:$H$1005,"November") -> 0 | Q23: =COUNTIFS('Annex 4.1 TA_CLUP'!$J$18:$J$1005,"1st",'Annex 4.1 TA_CLUP'!$H$18:$H$1005,"December") -> 0 | R23: =SUM(F23:H23) -> 4 | S23: =SUM(I23:K23) -> 0 | T23: =SUM(L23:N23) -> 0 | U23: =SUM(O23:Q23) -> 0 | V23: =SUM(F23:Q23) -> 4 | X23: Annex 4.1 TA_CLUP'!A1
C24: 1.2. No. of assistance provided: | F24: =COUNTIFS('Annex 4.1 TA_CLUP'!$D$18:$D$1005, "<>", 'Annex 4.1 TA_CLUP'!$H$18:$H$1005, "January") -> 1 | G24: =COUNTIFS('Annex 4.1 TA_CLUP'!$D$18:$D$1005, "<>", 'Annex 4.1 TA_CLUP'!$H$18:$H$1005, "February") -> 5 | H24: =COUNTIFS('Annex 4.1 TA_CLUP'!$D$18:$D$1005, "<>", 'Annex 4.1 TA_CLUP'!$H$18:$H$1005, "March") -> 0 | I24: =COUNTIFS('Annex 4.1 TA_CLUP'!$D$18:$D$1005, "<>", 'Annex 4.1 TA_CLUP'!$H$18:$H$1005, "April") -> 0 | J24: =COUNTIFS('Annex 4.1 TA_CLUP'!$D$18:$D$1005, "<>", 'Annex 4.1 TA_CLUP'!$H$18:$H$1005, "May") -> 0 | K24: =COUNTIFS('Annex 4.1 TA_CLUP'!$D$18:$D$1005, "<>", 'Annex 4.1 TA_CLUP'!$H$18:$H$1005, "June") -> 0 | L24: =COUNTIFS('Annex 4.1 TA_CLUP'!$D$18:$D$1005, "<>", 'Annex 4.1 TA_CLUP'!$H$18:$H$1005, "July") -> 0 | M24: =COUNTIFS('Annex 4.1 TA_CLUP'!$D$18:$D$1005, "<>", 'Annex 4.1 TA_CLUP'!$H$18:$H$1005, "August") -> 0 | N24: =COUNTIFS('Annex 4.1 TA_CLUP'!$D$18:$D$1005, "<>", 'Annex 4.1 TA_CLUP'!$H$18:$H$1005, "September") -> 0 | O24: =COUNTIFS('Annex 4.1 TA_CLUP'!$D$18:$D$1005, "<>", 'Annex 4.1 TA_CLUP'!$H$18:$H$1005, "October") -> 0 | P24: =COUNTIFS('Annex 4.1 TA_CLUP'!$D$18:$D$1005, "<>", 'Annex 4.1 TA_CLUP'!$H$18:$H$1005, "November") -> 0 | Q24: =COUNTIFS('Annex 4.1 TA_CLUP'!$D$18:$D$1005, "<>", 'Annex 4.1 TA_CLUP'!$H$18:$H$1005, "December") -> 0 | R24: =SUM(F24:H24) -> 6 | S24: =SUM(I24:K24) -> 0 | T24: =SUM(L24:N24) -> 0 | U24: =SUM(O24:Q24) -> 0 | V24: =SUM(F24:Q24) -> 6
D25: 1.2.1. No. of planned assistance | F25: =COUNTIFS('Annex 4.1 TA_CLUP'!$F$18:$F$1005,"Planned",'Annex 4.1 TA_CLUP'!$H$18:$H$1005,"January") -> 0 | G25: =COUNTIFS('Annex 4.1 TA_CLUP'!$F$18:$F$1005,"Planned",'Annex 4.1 TA_CLUP'!$H$18:$H$1005,"February") -> 0 | H25: =COUNTIFS('Annex 4.1 TA_CLUP'!$F$18:$F$1005,"Planned",'Annex 4.1 TA_CLUP'!$H$18:$H$1005,"March") -> 0 | I25: =COUNTIFS('Annex 4.1 TA_CLUP'!$F$18:$F$1005,"Planned",'Annex 4.1 TA_CLUP'!$H$18:$H$1005,"April") -> 0 | J25: =COUNTIFS('Annex 4.1 TA_CLUP'!$F$18:$F$1005,"Planned",'Annex 4.1 TA_CLUP'!$H$18:$H$1005,"May") -> 0 | K25: =COUNTIFS('Annex 4.1 TA_CLUP'!$F$18:$F$1005,"Planned",'Annex 4.1 TA_CLUP'!$H$18:$H$1005,"June") -> 0 | L25: =COUNTIFS('Annex 4.1 TA_CLUP'!$F$18:$F$1005,"Planned",'Annex 4.1 TA_CLUP'!$H$18:$H$1005,"July") -> 0 | M25: =COUNTIFS('Annex 4.1 TA_CLUP'!$F$18:$F$1005,"Planned",'Annex 4.1 TA_CLUP'!$H$18:$H$1005,"August") -> 0 | N25: =COUNTIFS('Annex 4.1 TA_CLUP'!$F$18:$F$1005,"Planned",'Annex 4.1 TA_CLUP'!$H$18:$H$1005,"September") -> 0 | O25: =COUNTIFS('Annex 4.1 TA_CLUP'!$F$18:$F$1005,"Planned",'Annex 4.1 TA_CLUP'!$H$18:$H$1005,"October") -> 0 | P25: =COUNTIFS('Annex 4.1 TA_CLUP'!$F$18:$F$1005,"Planned",'Annex 4.1 TA_CLUP'!$H$18:$H$1005,"November") -> 0 | Q25: =COUNTIFS('Annex 4.1 TA_CLUP'!$F$18:$F$1005,"Planned",'Annex 4.1 TA_CLUP'!$H$18:$H$1005,"December") -> 0 | R25: =SUM(F25:H25) -> 0 | S25: =SUM(I25:K25) -> 0 | T25: =SUM(L25:N25) -> 0 | U25: =SUM(O25:Q25) -> 0 | V25: =SUM(F25:Q25) -> 0
D26: 1.2.2. No. of requested (by demand) assistance | F26: =COUNTIFS('Annex 4.1 TA_CLUP'!$F$18:$F$1005,"Requested",'Annex 4.1 TA_CLUP'!$H$18:$H$1005,F11) -> 1 | G26: =COUNTIFS('Annex 4.1 TA_CLUP'!$F$18:$F$1005,"Requested",'Annex 4.1 TA_CLUP'!$H$18:$H$1005,G11) -> 5 | H26: =COUNTIFS('Annex 4.1 TA_CLUP'!$F$18:$F$1005,"Requested",'Annex 4.1 TA_CLUP'!$H$18:$H$1005,H11) -> 0 | I26: =COUNTIFS('Annex 4.1 TA_CLUP'!$F$18:$F$1005,"Requested",'Annex 4.1 TA_CLUP'!$H$18:$H$1005,I11) -> 0 | J26: =COUNTIFS('Annex 4.1 TA_CLUP'!$F$18:$F$1005,"Requested",'Annex 4.1 TA_CLUP'!$H$18:$H$1005,J11) -> 0 | K26: =COUNTIFS('Annex 4.1 TA_CLUP'!$F$18:$F$1005,"Requested",'Annex 4.1 TA_CLUP'!$H$18:$H$1005,K11) -> 0 | L26: =COUNTIFS('Annex 4.1 TA_CLUP'!$F$18:$F$1005,"Requested",'Annex 4.1 TA_CLUP'!$H$18:$H$1005,L11) -> 0 | M26: =COUNTIFS('Annex 4.1 TA_CLUP'!$F$18:$F$1005,"Requested",'Annex 4.1 TA_CLUP'!$H$18:$H$1005,M11) -> 0 | ... Q26: =COUNTIFS('Annex 4.1 TA_CLUP'!$F$18:$F$1005,"Requested",'Annex 4.1 TA_CLUP'!$H$18:$H$1005,Q11) -> 0 | R26: =SUM(F26:H26) -> 6 | S26: =SUM(I26:K26) -> 0 | T26: =SUM(L26:N26) -> 0 | U26: =SUM(O26:Q26) -> 0 | V26: =SUM(F26:Q26) -> 6
B27: 2 | C27: Technical assistance on the preparation of PDPFPs/PPFPs
C28: 2.1. No. of LGUs assisted on the preparation of PDPFPs/PPFPs (single counting) | E28: 1 | F28: =COUNTIFS('Annex 4.2 TA_PDPFP'!$I$18:$I$1000,"1st",'Annex 4.2 TA_PDPFP'!$G$18:$G$1000,'Accomplishment 2026'!F11) -> 0 | G28: =COUNTIFS('Annex 4.2 TA_PDPFP'!$I$18:$I$1000,"1st",'Annex 4.2 TA_PDPFP'!$G$18:$G$1000,'Accomplishment 2026'!G11) -> 0 | H28: =COUNTIFS('Annex 4.2 TA_PDPFP'!$I$18:$I$1000,"1st",'Annex 4.2 TA_PDPFP'!$G$18:$G$1000,'Accomplishment 2026'!H11) -> 0 | I28: =COUNTIFS('Annex 4.2 TA_PDPFP'!$I$18:$I$1000,"1st",'Annex 4.2 TA_PDPFP'!$G$18:$G$1000,'Accomplishment 2026'!I11) -> 0 | J28: =COUNTIFS('Annex 4.2 TA_PDPFP'!$I$18:$I$1000,"1st",'Annex 4.2 TA_PDPFP'!$G$18:$G$1000,'Accomplishment 2026'!J11) -> 0 | K28: =COUNTIFS('Annex 4.2 TA_PDPFP'!$I$18:$I$1000,"1st",'Annex 4.2 TA_PDPFP'!$G$18:$G$1000,'Accomplishment 2026'!K11) -> 0 | L28: =COUNTIFS('Annex 4.2 TA_PDPFP'!$I$18:$I$1000,"1st",'Annex 4.2 TA_PDPFP'!$G$18:$G$1000,'Accomplishment 2026'!L11) -> 0 | M28: =COUNTIFS('Annex 4.2 TA_PDPFP'!$I$18:$I$1000,"1st",'Annex 4.2 TA_PDPFP'!$G$18:$G$1000,'Accomplishment 2026'!M11) -> 0 | ... Q28: =COUNTIFS('Annex 4.2 TA_PDPFP'!$I$18:$I$1000,"1st",'Annex 4.2 TA_PDPFP'!$G$18:$G$1000,'Accomplishment 2026'!Q11) -> 0 | R28: =SUM(F28:H28) -> 0 | S28: =SUM(I28:K28) -> 0 | T28: =SUM(L28:N28) -> 0 | U28: =SUM(O28:Q28) -> 0 | V28: =SUM(F28:Q28) -> 0 | X28: Annex 4.2 TA_PDPFP'!A1
C29: 2.2. No. of assistance provided: | F29: =COUNTIFS('Annex 4.2 TA_PDPFP'!$C$18:$C$1000,"<>",'Annex 4.2 TA_PDPFP'!$G$18:$G$1000,'Accomplishment 2026'!F11) -> 0 | G29: =COUNTIFS('Annex 4.2 TA_PDPFP'!$C$18:$C$1000,"<>",'Annex 4.2 TA_PDPFP'!$G$18:$G$1000,'Accomplishment 2026'!G11) -> 0 | H29: =COUNTIFS('Annex 4.2 TA_PDPFP'!$C$18:$C$1000,"<>",'Annex 4.2 TA_PDPFP'!$G$18:$G$1000,'Accomplishment 2026'!H11) -> 0 | I29: =COUNTIFS('Annex 4.2 TA_PDPFP'!$C$18:$C$1000,"<>",'Annex 4.2 TA_PDPFP'!$G$18:$G$1000,'Accomplishment 2026'!I11) -> 0 | J29: =COUNTIFS('Annex 4.2 TA_PDPFP'!$C$18:$C$1000,"<>",'Annex 4.2 TA_PDPFP'!$G$18:$G$1000,'Accomplishment 2026'!J11) -> 0 | K29: =COUNTIFS('Annex 4.2 TA_PDPFP'!$C$18:$C$1000,"<>",'Annex 4.2 TA_PDPFP'!$G$18:$G$1000,'Accomplishment 2026'!K11) -> 0 | L29: =COUNTIFS('Annex 4.2 TA_PDPFP'!$C$18:$C$1000,"<>",'Annex 4.2 TA_PDPFP'!$G$18:$G$1000,'Accomplishment 2026'!L11) -> 0 | M29: =COUNTIFS('Annex 4.2 TA_PDPFP'!$C$18:$C$1000,"<>",'Annex 4.2 TA_PDPFP'!$G$18:$G$1000,'Accomplishment 2026'!M11) -> 0 | ... Q29: =COUNTIFS('Annex 4.2 TA_PDPFP'!$C$18:$C$1000,"<>",'Annex 4.2 TA_PDPFP'!$G$18:$G$1000,'Accomplishment 2026'!Q11) -> 0 | R29: =SUM(F29:H29) -> 0 | S29: =SUM(I29:K29) -> 0 | T29: =SUM(L29:N29) -> 0 | U29: =SUM(O29:Q29) -> 0 | V29: =SUM(F29:Q29) -> 0
D30: 2.2.1. No. of planned assistance | F30: =COUNTIFS('Annex 4.2 TA_PDPFP'!$E$18:$E$1000,"Planned",'Annex 4.2 TA_PDPFP'!$G$18:$G$1000,F11) -> 0 | G30: =COUNTIFS('Annex 4.2 TA_PDPFP'!$E$18:$E$1000,"Planned",'Annex 4.2 TA_PDPFP'!$G$18:$G$1000,G11) -> 0 | H30: =COUNTIFS('Annex 4.2 TA_PDPFP'!$E$18:$E$1000,"Planned",'Annex 4.2 TA_PDPFP'!$G$18:$G$1000,H11) -> 0 | I30: =COUNTIFS('Annex 4.2 TA_PDPFP'!$E$18:$E$1000,"Planned",'Annex 4.2 TA_PDPFP'!$G$18:$G$1000,I11) -> 0 | J30: =COUNTIFS('Annex 4.2 TA_PDPFP'!$E$18:$E$1000,"Planned",'Annex 4.2 TA_PDPFP'!$G$18:$G$1000,J11) -> 0 | K30: =COUNTIFS('Annex 4.2 TA_PDPFP'!$E$18:$E$1000,"Planned",'Annex 4.2 TA_PDPFP'!$G$18:$G$1000,K11) -> 0 | L30: =COUNTIFS('Annex 4.2 TA_PDPFP'!$E$18:$E$1000,"Planned",'Annex 4.2 TA_PDPFP'!$G$18:$G$1000,L11) -> 0 | M30: =COUNTIFS('Annex 4.2 TA_PDPFP'!$E$18:$E$1000,"Planned",'Annex 4.2 TA_PDPFP'!$G$18:$G$1000,M11) -> 0 | ... Q30: =COUNTIFS('Annex 4.2 TA_PDPFP'!$E$18:$E$1000,"Planned",'Annex 4.2 TA_PDPFP'!$G$18:$G$1000,Q11) -> 0 | R30: =SUM(F30:H30) -> 0 | S30: =SUM(I30:K30) -> 0 | T30: =SUM(L30:N30) -> 0 | U30: =SUM(O30:Q30) -> 0 | V30: =SUM(F30:Q30) -> 0
D31: 2.2.2. No. of requested (by demand) assistance | F31: =COUNTIFS('Annex 4.2 TA_PDPFP'!$E$18:$E$1000,"Requested",'Annex 4.2 TA_PDPFP'!$G$18:$G$1000,F11) -> 0 | G31: =COUNTIFS('Annex 4.2 TA_PDPFP'!$E$18:$E$1000,"Requested",'Annex 4.2 TA_PDPFP'!$G$18:$G$1000,G11) -> 0 | H31: =COUNTIFS('Annex 4.2 TA_PDPFP'!$E$18:$E$1000,"Requested",'Annex 4.2 TA_PDPFP'!$G$18:$G$1000,H11) -> 0 | I31: =COUNTIFS('Annex 4.2 TA_PDPFP'!$E$18:$E$1000,"Requested",'Annex 4.2 TA_PDPFP'!$G$18:$G$1000,I11) -> 0 | J31: =COUNTIFS('Annex 4.2 TA_PDPFP'!$E$18:$E$1000,"Requested",'Annex 4.2 TA_PDPFP'!$G$18:$G$1000,J11) -> 0 | K31: =COUNTIFS('Annex 4.2 TA_PDPFP'!$E$18:$E$1000,"Requested",'Annex 4.2 TA_PDPFP'!$G$18:$G$1000,K11) -> 0 | L31: =COUNTIFS('Annex 4.2 TA_PDPFP'!$E$18:$E$1000,"Requested",'Annex 4.2 TA_PDPFP'!$G$18:$G$1000,L11) -> 0 | M31: =COUNTIFS('Annex 4.2 TA_PDPFP'!$E$18:$E$1000,"Requested",'Annex 4.2 TA_PDPFP'!$G$18:$G$1000,M11) -> 0 | ... Q31: =COUNTIFS('Annex 4.2 TA_PDPFP'!$E$18:$E$1000,"Requested",'Annex 4.2 TA_PDPFP'!$G$18:$G$1000,Q11) -> 0 | R31: =SUM(F31:H31) -> 0 | S31: =SUM(I31:K31) -> 0 | T31: =SUM(L31:N31) -> 0 | U31: =SUM(O31:Q31) -> 0 | V31: =SUM(F31:Q31) -> 0
B32: 3 | C32: Technical assistance on the preparation of enhanced housing sub-sector (LSP)
C33: 3.1. No. of LGUs assisted on preparation of enhanced housing sub-sector in preparation for integration to CLUP (single counting) | E33: 3 | F33: =COUNTIFS('Annex 4.3 TA_HouSub'!$J$18:$J$999,"1st",'Annex 4.3 TA_HouSub'!$H$18:$H$999,F11) -> 0 | G33: =COUNTIFS('Annex 4.3 TA_HouSub'!$J$18:$J$999,"1st",'Annex 4.3 TA_HouSub'!$H$18:$H$999,G11) -> 2 | H33: =COUNTIFS('Annex 4.3 TA_HouSub'!$J$18:$J$999,"1st",'Annex 4.3 TA_HouSub'!$H$18:$H$999,H11) -> 0 | I33: =COUNTIFS('Annex 4.3 TA_HouSub'!$J$18:$J$999,"1st",'Annex 4.3 TA_HouSub'!$H$18:$H$999,I11) -> 0 | J33: =COUNTIFS('Annex 4.3 TA_HouSub'!$J$18:$J$999,"1st",'Annex 4.3 TA_HouSub'!$H$18:$H$999,J11) -> 0 | K33: =COUNTIFS('Annex 4.3 TA_HouSub'!$J$18:$J$999,"1st",'Annex 4.3 TA_HouSub'!$H$18:$H$999,K11) -> 0 | L33: =COUNTIFS('Annex 4.3 TA_HouSub'!$J$18:$J$999,"1st",'Annex 4.3 TA_HouSub'!$H$18:$H$999,L11) -> 0 | M33: =COUNTIFS('Annex 4.3 TA_HouSub'!$J$18:$J$999,"1st",'Annex 4.3 TA_HouSub'!$H$18:$H$999,M11) -> 0 | ... Q33: =COUNTIFS('Annex 4.3 TA_HouSub'!$J$18:$J$999,"1st",'Annex 4.3 TA_HouSub'!$H$18:$H$999,Q11) -> 0 | R33: =SUM(F33:H33) -> 2 | S33: =SUM(I33:K33) -> 0 | T33: =SUM(L33:N33) -> 0 | U33: =SUM(O33:Q33) -> 0 | V33: =SUM(F33:Q33) -> 2 | X33: Annex 4.3 TA_HouSub'!A1
C34: 3.2. No. of assistance provided: | F34: =COUNTIFS('Annex 4.3 TA_HouSub'!$D$18:$D$999,"<>",'Annex 4.3 TA_HouSub'!$H$18:$H$999,F11) -> 0 | G34: =COUNTIFS('Annex 4.3 TA_HouSub'!$D$18:$D$999,"<>",'Annex 4.3 TA_HouSub'!$H$18:$H$999,G11) -> 2 | H34: =COUNTIFS('Annex 4.3 TA_HouSub'!$D$18:$D$999,"<>",'Annex 4.3 TA_HouSub'!$H$18:$H$999,H11) -> 0 | I34: =COUNTIFS('Annex 4.3 TA_HouSub'!$D$18:$D$999,"<>",'Annex 4.3 TA_HouSub'!$H$18:$H$999,I11) -> 0 | J34: =COUNTIFS('Annex 4.3 TA_HouSub'!$D$18:$D$999,"<>",'Annex 4.3 TA_HouSub'!$H$18:$H$999,J11) -> 0 | K34: =COUNTIFS('Annex 4.3 TA_HouSub'!$D$18:$D$999,"<>",'Annex 4.3 TA_HouSub'!$H$18:$H$999,K11) -> 0 | L34: =COUNTIFS('Annex 4.3 TA_HouSub'!$D$18:$D$999,"<>",'Annex 4.3 TA_HouSub'!$H$18:$H$999,L11) -> 0 | M34: =COUNTIFS('Annex 4.3 TA_HouSub'!$D$18:$D$999,"<>",'Annex 4.3 TA_HouSub'!$H$18:$H$999,M11) -> 0 | ... Q34: =COUNTIFS('Annex 4.3 TA_HouSub'!$D$18:$D$999,"<>",'Annex 4.3 TA_HouSub'!$H$18:$H$999,Q11) -> 0 | R34: =SUM(F34:H34) -> 2 | S34: =SUM(I34:K34) -> 0 | T34: =SUM(L34:N34) -> 0 | U34: =SUM(O34:Q34) -> 0 | V34: =SUM(F34:Q34) -> 2
D35: 3.2.1. No. of planned assistance | F35: =COUNTIFS('Annex 4.3 TA_HouSub'!$F$18:$F$999,"Planned",'Annex 4.3 TA_HouSub'!$H$18:$H$999,F11) -> 0 | G35: =COUNTIFS('Annex 4.3 TA_HouSub'!$F$18:$F$999,"Planned",'Annex 4.3 TA_HouSub'!$H$18:$H$999,G11) -> 0 | H35: =COUNTIFS('Annex 4.3 TA_HouSub'!$F$18:$F$999,"Planned",'Annex 4.3 TA_HouSub'!$H$18:$H$999,H11) -> 0 | I35: =COUNTIFS('Annex 4.3 TA_HouSub'!$F$18:$F$999,"Planned",'Annex 4.3 TA_HouSub'!$H$18:$H$999,I11) -> 0 | J35: =COUNTIFS('Annex 4.3 TA_HouSub'!$F$18:$F$999,"Planned",'Annex 4.3 TA_HouSub'!$H$18:$H$999,J11) -> 0 | K35: =COUNTIFS('Annex 4.3 TA_HouSub'!$F$18:$F$999,"Planned",'Annex 4.3 TA_HouSub'!$H$18:$H$999,K11) -> 0 | L35: =COUNTIFS('Annex 4.3 TA_HouSub'!$F$18:$F$999,"Planned",'Annex 4.3 TA_HouSub'!$H$18:$H$999,L11) -> 0 | M35: =COUNTIFS('Annex 4.3 TA_HouSub'!$F$18:$F$999,"Planned",'Annex 4.3 TA_HouSub'!$H$18:$H$999,M11) -> 0 | ... Q35: =COUNTIFS('Annex 4.3 TA_HouSub'!$F$18:$F$999,"Planned",'Annex 4.3 TA_HouSub'!$H$18:$H$999,Q11) -> 0 | R35: =SUM(F35:H35) -> 0 | S35: =SUM(I35:K35) -> 0 | T35: =SUM(L35:N35) -> 0 | U35: =SUM(O35:Q35) -> 0 | V35: =SUM(F35:Q35) -> 0
D36: 3.2.2. No. of requested (by demand) assistance | F36: =COUNTIFS('Annex 4.3 TA_HouSub'!$F$18:$F$999,"Requested",'Annex 4.3 TA_HouSub'!$H$18:$H$999,F11) -> 0 | G36: =COUNTIFS('Annex 4.3 TA_HouSub'!$F$18:$F$999,"Requested",'Annex 4.3 TA_HouSub'!$H$18:$H$999,G11) -> 2 | H36: =COUNTIFS('Annex 4.3 TA_HouSub'!$F$18:$F$999,"Requested",'Annex 4.3 TA_HouSub'!$H$18:$H$999,H11) -> 0 | I36: =COUNTIFS('Annex 4.3 TA_HouSub'!$F$18:$F$999,"Requested",'Annex 4.3 TA_HouSub'!$H$18:$H$999,I11) -> 0 | J36: =COUNTIFS('Annex 4.3 TA_HouSub'!$F$18:$F$999,"Requested",'Annex 4.3 TA_HouSub'!$H$18:$H$999,J11) -> 0 | K36: =COUNTIFS('Annex 4.3 TA_HouSub'!$F$18:$F$999,"Requested",'Annex 4.3 TA_HouSub'!$H$18:$H$999,K11) -> 0 | L36: =COUNTIFS('Annex 4.3 TA_HouSub'!$F$18:$F$999,"Requested",'Annex 4.3 TA_HouSub'!$H$18:$H$999,L11) -> 0 | M36: =COUNTIFS('Annex 4.3 TA_HouSub'!$F$18:$F$999,"Requested",'Annex 4.3 TA_HouSub'!$H$18:$H$999,M11) -> 0 | ... Q36: =COUNTIFS('Annex 4.3 TA_HouSub'!$F$18:$F$999,"Requested",'Annex 4.3 TA_HouSub'!$H$18:$H$999,Q11) -> 0 | R36: =SUM(F36:H36) -> 2 | S36: =SUM(I36:K36) -> 0 | T36: =SUM(L36:N36) -> 0 | U36: =SUM(O36:Q36) -> 0 | V36: =SUM(F36:Q36) -> 2
B37: 4 | C37: Technical assistance on the review and approval process of CLUPs/ZOs
